{
 "cells": [
  {
   "cell_type": "markdown",
   "metadata": {},
   "source": [
    "There are two types of errors that typically occur when writing programs. \n",
    "일반적으로 프로그램을 작성할때 에러 유형 2개가 있다.  \n",
    "The first, known as a syntax error, simply means that the programmer has made a mistake in the structure of a statement or expression.  \n",
    "첫번째로 구문에러로 간단히 프로그래머가 구문 혹은 표현에 있어서 실수를 의미한다.  \n",
    "For example, it is incorrect to write a for statement and forget the colon.  \n",
    "예를들어, 구문을 부정확하게 쓰거나 콜론을 잊은 것이다.  \n",
    "```\n",
    ">>> for i in range(10)\n",
    "SyntaxError: invalid syntax (<pyshell#61>, line 1)\n",
    "```\n",
    "In this case, the Python interpreter has found that it cannot complete the processing of this instruction since it does not conform to the rules of the language.  \n",
    "이경우, 파이썬 인터프리터는 언어의 규칙이 승인되지 않기 때문에 이 구성의 처리를 완료하지 못하는 것을 찾았다.   \n",
    "\n",
    "Syntax errors are usually more frequent when you are first learning a language.   \n",
    "구문 에러는 언어를 처음배울때 일반적으로 많이 발생한다.  \n",
    "The other type of error, known as a logic error, denotes a situation where the program executes but gives the wrong result. \n",
    "다른 에러 유형은 로직에러로  프로그램 실행시  틀린결과를 받는 상황을 의미한다.  \n",
    "This can be due to an error in the underlying algorithm or an error in your translation of that algorithm.  \n",
    "기본 알고리즘 에러거나 알고리즘의 전송에러로 발생할 수있다.  \n",
    "In some cases, logic errors lead to very bad situations such as trying to divide by zero or trying to access an item in a list where the index of the item is outside the bounds of the list.  \n",
    "로직에러의 일부 경우에는 0으로 나누거나 list 밖의 item 인덱스에 접근하는 경우의 매우나쁜 상황이 발생한다.\n",
    "In this case, the logic error leads to a runtime error that causes the program to terminate.  \n",
    "로직에러인경우 프로그램을 종료시키는 런타임에러가 발생한다.  \n",
    "These types of runtime errors are typically called exceptions.  \n",
    "런타임 에러 유형은 전형적으로 예외라고 불린다.  \n",
    "\n",
    "Most of the time, beginning programmers simply think of exceptions as fatal runtime errors that cause the end of execution.  \n",
    "대부분의 경우 프로그래머를 시작하는 것은 예외를 실행의 원인이되는 치명적인 런타임 오류라고 생각한다. \n",
    "However, most programming languages provide a way to deal with these errors that will allow the programmer to have some type of intervention if they so choose.  \n",
    "그러나 대부분의 프로그래밍 언어는 이러한 오류를 처리 할 수있는 방법을 제공하여 프로그래머가 어떤 유형의 개입을 할 수 있게한다. \n",
    "In addition, programmers can create their own exceptions if they detect a situation in the program execution that warrants it.  \n",
    "게다가 프로그래머는 프로그램 실행의 보증할 상황에서 방어처리로 예외를 생성 할 수 있다.  \n",
    "When an exception occurs, we say that it has been “raised.” You can “handle” the exception that has been raised by using a try statement.  \n",
    "예외 발생시 raised 되었다고 말한다. try 문을 사용하여 예외를 처리 할 수 있다. \n",
    "For example, consider the following session that asks the user for an integer and then calls the square root function from the math library.   \n",
    "예를 들어, 사용자에게 정수를 요청한 다음 Math 라이브러리에서 제곱근 함수를 호출하는 다음 세션을 고려해봐라.  \n",
    "If the user enters a value that is greater than or equal to 0, the print will show the square root.   \n",
    "사용자가 0보다 크거나 같은 값을 입력하면  제곱근이 표시된다.  \n",
    "However, if the user enters a negative value, the square root function will report a ValueError exception.  \n",
    "그러나, 음수값을 입력한다면, 제곱근 함수는 ValueError 예외를 알려줄 것이다.  \n",
    "```\n",
    ">>> anumber = int(input(\"Please enter an integer \"))\n",
    "Please enter an integer -23\n",
    ">>> print(math.sqrt(anumber))\n",
    "Traceback (most recent call last):\n",
    "  File \"<pyshell#102>\", line 1, in <module>\n",
    "    print(math.sqrt(anumber))\n",
    "ValueError: math domain error\n",
    ">>>  \n",
    "```\n",
    "\n",
    "We can handle this exception by calling the print function from within a try block.   \n",
    "try block과 함께 print 함수 호출로 예외를 처리할 수 있다.  \n",
    "A corresponding except block “catches” the exception and prints a message back to the user in the event that an exception occurs.  For example:  \n",
    "\n",
    "해당 예외 블록은 예외를 \"catch\"하고 예외가 발생하는 경우 사용자에게 메시지를 다시 보여준다.  \n",
    "\n",
    "```\n",
    ">>> try:\n",
    "       print(math.sqrt(anumber))\n",
    "    except:\n",
    "       print(\"Bad Value for square root\")\n",
    "       print(\"Using absolute value instead\")\n",
    "       print(math.sqrt(abs(anumber)))\n",
    "\n",
    "Bad Value for square root\n",
    "Using absolute value instead\n",
    "4.79583152331\n",
    ">>>\n",
    "```\n",
    "\n",
    "will catch the fact that an exception is raised by sqrt and will instead print the messages back to the user and use the absolute value to be sure that we are taking the square root of a non-negative number.   \n",
    "예외가 sqrt에 의해 발생된다는 사실을 알고 메시지를 사용자에게 다시 출력하고 절대 값을 사용하여 음이 아닌 숫자의 제곱근을 얻는지 확인한다. \n",
    "This means that the program will not terminate but instead will continue on to the next statements.  \n",
    "이 프로그램의 의미는 끝내는 것이 아니고 다음문을 지속하기 위해 대신하는것 이다.  \n",
    "It is also possible for a programmer to cause a runtime exception by using the raise statement.   \n",
    "프로그래머가 raise 문을 사용하여 런타임 예외를 발생시킬 수도 있다.  \n",
    "For example, instead of calling the square root function with a negative number, we could have checked the value first and then raised our own exception.   \n",
    "예를들면, 음수로 제곱근 함수를 호출하는 대신에 우선 값을 체크하고 자체 예외를 발생시킨다.  \n",
    "The code fragment below shows the result of creating a new RuntimeError exception.   \n",
    "아래 코드는 신규 런타임에러 예외 생성의 결과를 보여준다.  \n",
    "Note that the program would still terminate but now the exception that caused the termination is something explicitly created by the programmer.  \n",
    "프로그램은 여전히 종료되지만 종료를 야기한 예외는 프로그래머가 명시 적으로 작성한 것이다. \n",
    "\n",
    "```\n",
    "\n",
    ">>> if anumber < 0:\n",
    "...    raise RuntimeError(\"You can't use a negative number\")\n",
    "... else:\n",
    "...    print(math.sqrt(anumber))\n",
    "...\n",
    "Traceback (most recent call last):\n",
    "  File \"<stdin>\", line 2, in <module>\n",
    "RuntimeError: You can't use a negative number\n",
    ">>>\n",
    "\n",
    "```\n",
    "There are many kinds of exceptions that can be raised in addition to the RuntimeError shown above. \n",
    "위에 보여준 런타임에러외에 발생할 수 있는 많은 종류의 예외가 있다.  \n",
    "See the Python reference manual for a list of all the available exception types and for how to create your own.  \n"
   ]
  }
 ],
 "metadata": {
  "kernelspec": {
   "display_name": "Python 3",
   "language": "python",
   "name": "python3"
  },
  "language_info": {
   "codemirror_mode": {
    "name": "ipython",
    "version": 3
   },
   "file_extension": ".py",
   "mimetype": "text/x-python",
   "name": "python",
   "nbconvert_exporter": "python",
   "pygments_lexer": "ipython3",
   "version": "3.7.3"
  }
 },
 "nbformat": 4,
 "nbformat_minor": 2
}
